Workbook

Sheet 00_Anleitung
A1: EU AI Act — Arbeitshilfe zur Umsetzung
A2: Fassung 1.1 · Rechtsstand: 29.07.2026 · Verordnung (EU) 2024/1689 in der Fassung der Verordnung (EU) 2026/1744 (Digital Omnibus, in Kraft seit 27.07.2026)
B5: Wichtiger Hinweis
B6: Keine Rechtsberatung | C6: Diese Arbeitshilfe ist ein Strukturierungswerkzeug, keine Rechtsberatung. Ob eine Pflicht im konkreten Fall greift, hängt von Umständen ab, die hier nicht bekannt sind. Was Blatt 03 ausgibt, ist ein automatischer PRÜFUNGSVORSCHLAG auf Basis Ihrer Eingaben — KEINE FREIGABEENTSCHEIDUNG und kein Ersatz für eine juristische Prüfung. Solange Spalte O nicht auf „Ja“ steht, gilt jede Einstufung als Arbeitsannahme.
B7: Reichweite der Verschiebung — bitte einmal lesen | C7: Der Gesetzgeber hat ausdrücklich nur Kapitel III Abschnitte 1, 2 und 3 verschoben (Art. 113 Abs. 3 lit. c n. F.). Konformitätsbewertung und Registrierung (Art. 40–49), Beobachtung nach dem Inverkehrbringen und Vorfallmeldung (Art. 72, 73), das Recht auf Erläuterung (Art. 86) und die Transparenzpflichten (Art. 50) sind vom Wortlaut NICHT erfasst — sie gelten seit 02.08.2026. Diese Arbeitshilfe plant sie dennoch zum jeweiligen Hochrisiko-Termin, weil sie ohne anwendbaren Art. 6 praktisch leerlaufen. Das ist eine ARBEITSANNAHME, nicht anwaltlich bestätigt. Halten Sie je System fest: gesetzlicher Wortlaut / geplante Frist / ob und durch wen bestätigt.
B8: Prüfdaten sind fest, nicht dynamisch | C8: Die Felder „Geprüft am“ auf den Blättern 02 und 03 sind manuelle Datumsfelder ohne Formel. Ein abgeschlossener Prüfeintrag bleibt beim nächsten Öffnen der Datei unverändert — sonst wäre er als Nachweis wertlos. Nur der Terminstatus auf Blatt 05 rechnet bewusst gegen das heutige Datum, weil er eine Steuerungs- und keine Nachweisgröße ist.
B9: Rechtsstand prüfen | C9: Stand dieser Datei: 29.07.2026. Die KI-Verordnung wurde zuletzt am 24.07.2026 geändert (VO (EU) 2026/1744, in Kraft seit 27.07.2026). Prüfen Sie vor jeder Nutzung, ob ein neuerer Stand vorliegt. Alle Fundstellen und Quellen finden Sie auf Blatt 07_Quellen.
B11: So arbeiten Sie mit der Datei
B12: Farbcode | C12: GELB hinterlegte Zellen sind Eingabefelder — hier tragen Sie ein. GRAUE Zellen sind vorgegeben oder berechnet und sollten nicht verändert werden; auf Blatt 04 enthalten sie den Pflichtenkatalog (Spalten A–G) und die Ampel-Formel (Spalte N). Blaue Kopfzeilen kennzeichnen Spaltenüberschriften.
B13: Reihenfolge | C13: 1. Blatt 01 KI-Inventar füllen (jedes System eine Zeile). 2. Blatt 02 Rollen-Check je System beantworten. 3. Blatt 03 Risiko-Einstufung je System beantworten. 4. Blatt 04 Pflichten-Matrix durchgehen und Relevanz sowie Status setzen. 5. Lücken in Blatt 05 Maßnahmenplan überführen. 6. Blatt 06 Dashboard zeigt den Stand.
B14: Beispiel | C14: Die produktiven Blätter 01 bis 05 starten leer — im Auslieferungszustand zeigt das Dashboard deshalb durchgehend 0. Ein vollständig durchgerechneter Musterfall steht auf Blatt 09_Beispiel; er enthält keine Formeln und wird nicht mitgezählt.
B15: System-IDs | C15: Die IDs (KI-001 ff.) werden auf Blatt 01 vergeben und auf den Blättern 02, 03 und 05 per Dropdown ausgewählt. Die Bezeichnung wird dann automatisch übernommen.
B17: Aufbau der Datei
B18: 01_KI-Inventar | C18: Alle im Unternehmen eingesetzten oder geplanten KI-Systeme. Grundlage für alles Weitere.
B19: 02_Rollen-Check | C19: Bestimmt je System, ob Sie Anbieter, Betreiber oder beides sind — inkl. Rollenwechsel nach Art. 25.
B20: 03_Risiko-Einstufung | C20: Führt je System durch die Prüfkette: verboten → Hochrisiko Anhang I (Abschnitt A oder B!) → Hochrisiko Anhang III → Transparenz → gering. Ergibt einen Prüfungsvorschlag, eine Frist und einen Bestätigungsstatus.
B21: 04_Pflichten-Matrix | C21: Katalog der Pflichten mit Fundstelle, Rolle, Risikoklasse und Frist. Hier tragen Sie Relevanz, Status und Verantwortliche ein.
B22: 05_Maßnahmenplan | C22: Offene Punkte aus Blatt 04 mit Maßnahme, Termin und Fortschritt.
B23: 06_Dashboard | C23: Auswertung: Anzahl Systeme je Klasse, Erfüllungsgrad, kritische Fristen.
B24: 07_Quellen | C24: Fundstellenregister mit Links — damit jede Angabe nachprüfbar bleibt.
B25: 08_Register | C25: Auswahllisten für die Dropdown-Felder. Nur ändern, wenn Sie die Systematik anpassen wollen.
B26: 09_Beispiel | C26: Ausgefüllter Musterfall zum Nachvollziehen — reiner Text, ohne Formeln, ohne Auswirkung auf das Dashboard.
B28: Anhang I: Abschnitt A oder Abschnitt B?
B29: Warum das zuerst geklärt werden muss | C29: Für Anhang I Abschnitt A gilt das volle Kapitel III der KI-Verordnung ab 02.08.2028. Für Anhang I Abschnitt B gelten nach Art. 2 Abs. 2 n. F. NUR Art. 6 Abs. 1, Art. 60a und Art. 102–112; Art. 57, 58 und 59 nur, soweit das Sektorrecht die Anforderungen übernommen hat. Solange der Abschnitt nicht bestimmt ist, gibt Blatt 03 bewusst keine Frist aus.
B30: Abschnitt A | C30: u. a. Spielzeug, Aufzüge, Geräte in explosionsgefährdeten Bereichen, Funkanlagen, Druckgeräte, Seilbahnen, persönliche Schutzausrüstung, Gasverbrennungsgeräte, Medizinprodukte, In-vitro-Diagnostika.
B31: Abschnitt B | C31: Zivilluftfahrt, Kraftfahrzeuge, Schiffsausrüstung, Eisenbahn — und seit Juli 2026 die Maschinenverordnung (EU) 2023/1230, die zuvor in Abschnitt A stand. Achtung: „Kapitel III gilt nicht“ wäre zu grob — Art. 6 Abs. 1 gilt weiter, das System bleibt ein Hochrisiko-KI-System. Nicht anwendbar sind die Anforderungs- und Pflichtenkapitel sowie Art. 50, Art. 72, Art. 73 und Art. 99.
B33: Die wichtigsten Fristen
B34: gilt bereits | C34: 02.02.2025 KI-Kompetenz (Art. 4) und verbotene Praktiken (Art. 5) · 02.08.2025 GPAI-Pflichten, Governance, Sanktionen
B35: 27.07.2026 | C35: Digital Omnibus in Kraft: Art. 102–110 KI-VO anwendbar; neue Rechtsgrundlage Art. 4a (Bias-Erkennung mit besonderen Datenkategorien) anwendbar
B36: 02.08.2026 | C36: Allgemeiner Geltungsbeginn — insbesondere Transparenzpflichten nach Art. 50
B37: 02.12.2026 | C37: Neue Verbote NCII und CSAM (Art. 5 Abs. 1 lit. ba und bb) · Kennzeichnungspflicht für generative Bestandssysteme (Art. 50 Abs. 2 i. V. m. Art. 111 Abs. 4)
B38: 02.12.2027 | C38: Pflichten für Hochrisiko-KI nach Anhang III (eigenständige Systeme) — Kapitel III Abschnitte 1, 2 und 3
B39: 02.08.2028 | C39: Pflichten für Hochrisiko-KI nach Anhang I Abschnitt A. Für Anhang I Abschnitt B (u. a. Maschinen, Kfz, Eisenbahn) gelten nur Art. 6 Abs. 1, Art. 60a und Art. 102–112 (Art. 2 Abs. 2 n. F.) — im Übrigen greift das Sektorrecht
B40: 02.08.2027 | C40: GPAI-Modelle, die vor dem 02.08.2025 in Verkehr gebracht wurden, müssen konform sein (Art. 111 Abs. 3); KI-Reallabore einsatzbereit
B41: 02.08.2030 / 31.12.2030 | C41: Hochrisiko-Bestandssysteme in Behördennutzung (Art. 111 Abs. 2) bzw. KI in IT-Großsystemen nach Anhang X (Art. 111 Abs. 1)
B42: Bestandsschutz | C42: Hochrisiko-Systeme, die vor dem jeweiligen Geltungsbeginn in Verkehr gebracht wurden, unterliegen der Verordnung nur bei erheblicher Änderung der Konzeption. Maßgeblich sind Art und Modell des Systems; entscheidend ist das Datum der ersten Einheit (Art. 111 Abs. 2 n. F., ErwG 39).
B44: Angaben zu Ihrem Unternehmen
B45: Unternehmensgröße
C46: Steuert die Erleichterungen nach Art. 11 Abs. 1 UAbs. 2 und Art. 63 Abs. 1 n. F. sowie die Bußgeld-Deckelung nach Art. 99 Abs. 6 (KMU: Absätze 3, 4 und 5) bzw. Abs. 6a n. F. (kleine Midcaps: nur Absätze 4 und 5 — bei Art. 5 gilt für sie KEINE Deckelung).
B47: Sind wir Anbieter eines KI-Modells mit allgemeinem Verwendungszweck (GPAI)?
...

Sheet 01_KI-Inventar
A1: 01 — KI-Inventar
A2: Jede Zeile ein KI-System. Auch KI, die in eingekaufter Software eingebettet ist, gehört hierher. Das Blatt startet leer — ein ausgefülltes Beispiel finden Sie auf Blatt 09_Beispiel.
A5: System-ID | B5: Bezeichnung | C5: Anbieter / Hersteller | D5: Zweck und Anwendungsfall | E5: Fachbereich | F5: Verarbeitete Datenarten | G5: Personenbezug | H5: Einsatzstatus | I5: Fachlich verantwortlich | J5: Vertrag / Bezugsquelle | K5: Bemerkung
A6: =IF(B6="","","KI-"&TEXT(ROW()-5,"000"))
A7: =IF(B7="","","KI-"&TEXT(ROW()-5,"000"))
A8: =IF(B8="","","KI-"&TEXT(ROW()-5,"000"))
A9: =IF(B9="","","KI-"&TEXT(ROW()-5,"000"))
A10: =IF(B10="","","KI-"&TEXT(ROW()-5,"000"))
A11: =IF(B11="","","KI-"&TEXT(ROW()-5,"000"))
A12: =IF(B12="","","KI-"&TEXT(ROW()-5,"000"))
A13: =IF(B13="","","KI-"&TEXT(ROW()-5,"000"))
A14: =IF(B14="","","KI-"&TEXT(ROW()-5,"000"))
A15: =IF(B15="","","KI-"&TEXT(ROW()-5,"000"))
A16: =IF(B16="","","KI-"&TEXT(ROW()-5,"000"))
A17: =IF(B17="","","KI-"&TEXT(ROW()-5,"000"))
... A65: =IF(B65="","","KI-"&TEXT(ROW()-5,"000"))

Sheet 02_Rollen-Check
A1: 02 — Rollen-Check (Anbieter oder Betreiber?)
A2: Je System beantworten. Achtung Art. 25: Eigenlabeling, wesentliche Veränderung oder Zweckänderung machen aus einem Betreiber einen Anbieter — mit allen Pflichten nach Art. 16.
A5: System-ID | B5: Bezeichnung (autom.) | C5: Entwickeln wir es (oder lassen entwickeln) und bringen es unter eigenem Namen in Verkehr / nehmen es in Betrieb? Art. 3 Nr. 3 | D5: Verwenden wir es in eigener beruflicher Verantwortung? Art. 3 Nr. 4 | E5: Eigenlabeling auf fremdem Hochrisiko-System? Art. 25 Abs. 1 lit. a | F5: Wesentliche Veränderung eines Hochrisiko-Systems? Art. 25 Abs. 1 lit. b | G5: Zweckänderung, die zum Hochrisiko-System führt? Art. 25 Abs. 1 lit. c | H5: Bringen wir es als Produkthersteller mit unserem Produkt unter eigenem Namen in Verkehr? Art. 25 Abs. 3 | I5: Ergebnis: Rolle (autom.) | J5: Hinweis (autom.) | K5: Geprüft am | L5: Geprüft von
B6: =IF(A6="","",IFERROR(INDEX('01_KI-Inventar'!$B$6:$B$65,MATCH(A6,'01_KI-Inventar'!$A$6:$A$65,0)),"")) | I6: =IF(A6="","",IF(OR(C6="Ja",E6="Ja",F6="Ja",G6="Ja",H6="Ja"),IF(D6="Ja","Anbieter und Betreiber","Anbieter"),IF(D6="Ja","Betreiber",IF(COUNTA(C6:H6)=6,"keine Anbieter-/Betreiberrolle","noch offen")))) | J6: =IF(A6="","",IF(OR(E6="Ja",F6="Ja",G6="Ja",H6="Ja"),IF(D6="Ja","Rollenwechsel nach Art. 25 — Anbieterpflichten (Art. 16) UND Betreiberpflichten (Art. 26)","Rollenwechsel nach Art. 25 — volle Anbieterpflichten nach Art. 16"),IF(AND(C6="Ja",D6="Ja"),"Anbieterpflichten (Art. 16) UND Betreiberpflichten (Art. 26)",IF(C6="Ja","Anbieterpflichten nach Art. 16",IF(D6="Ja","Betreiberpflichten nach Art. 26",IF(COUNTA(C6:H6)=6,"keine Anbieter-/Betreiberrolle — Einführer-/Händlerpflichten (Art. 23, 24) prüfen","noch offen — bitte alle Fragen beantworten"))))))
B7: =IF(A7="","",IFERROR(INDEX('01_KI-Inventar'!$B$6:$B$65,MATCH(A7,'01_KI-Inventar'!$A$6:$A$65,0)),"")) | I7: =IF(A7="","",IF(OR(C7="Ja",E7="Ja",F7="Ja",G7="Ja",H7="Ja"),IF(D7="Ja","Anbieter und Betreiber","Anbieter"),IF(D7="Ja","Betreiber",IF(COUNTA(C7:H7)=6,"keine Anbieter-/Betreiberrolle","noch offen")))) | J7: =IF(A7="","",IF(OR(E7="Ja",F7="Ja",G7="Ja",H7="Ja"),IF(D7="Ja","Rollenwechsel nach Art. 25 — Anbieterpflichten (Art. 16) UND Betreiberpflichten (Art. 26)","Rollenwechsel nach Art. 25 — volle Anbieterpflichten nach Art. 16"),IF(AND(C7="Ja",D7="Ja"),"Anbieterpflichten (Art. 16) UND Betreiberpflichten (Art. 26)",IF(C7="Ja","Anbieterpflichten nach Art. 16",IF(D7="Ja","Betreiberpflichten nach Art. 26",IF(COUNTA(C7:H7)=6,"keine Anbieter-/Betreiberrolle — Einführer-/Händlerpflichten (Art. 23, 24) prüfen","noch offen — bitte alle Fragen beantworten"))))))
B8: =IF(A8="","",IFERROR(INDEX('01_KI-Inventar'!$B$6:$B$65,MATCH(A8,'01_KI-Inventar'!$A$6:$A$65,0)),"")) | I8: =IF(A8="","",IF(OR(C8="Ja",E8="Ja",F8="Ja",G8="Ja",H8="Ja"),IF(D8="Ja","Anbieter und Betreiber","Anbieter"),IF(D8="Ja","Betreiber",IF(COUNTA(C8:H8)=6,"keine Anbieter-/Betreiberrolle","noch offen")))) | J8: =IF(A8="","",IF(OR(E8="Ja",F8="Ja",G8="Ja",H8="Ja"),IF(D8="Ja","Rollenwechsel nach Art. 25 — Anbieterpflichten (Art. 16) UND Betreiberpflichten (Art. 26)","Rollenwechsel nach Art. 25 — volle Anbieterpflichten nach Art. 16"),IF(AND(C8="Ja",D8="Ja"),"Anbieterpflichten (Art. 16) UND Betreiberpflichten (Art. 26)",IF(C8="Ja","Anbieterpflichten nach Art. 16",IF(D8="Ja","Betreiberpflichten nach Art. 26",IF(COUNTA(C8:H8)=6,"keine Anbieter-/Betreiberrolle — Einführer-/Händlerpflichten (Art. 23, 24) prüfen","noch offen — bitte alle Fragen beantworten"))))))
B9: =IF(A9="","",IFERROR(INDEX('01_KI-Inventar'!$B$6:$B$65,MATCH(A9,'01_KI-Inventar'!$A$6:$A$65,0)),"")) | I9: =IF(A9="","",IF(OR(C9="Ja",E9="Ja",F9="Ja",G9="Ja",H9="Ja"),IF(D9="Ja","Anbieter und Betreiber","Anbieter"),IF(D9="Ja","Betreiber",IF(COUNTA(C9:H9)=6,"keine Anbieter-/Betreiberrolle","noch offen")))) | J9: =IF(A9="","",IF(OR(E9="Ja",F9="Ja",G9="Ja",H9="Ja"),IF(D9="Ja","Rollenwechsel nach Art. 25 — Anbieterpflichten (Art. 16) UND Betreiberpflichten (Art. 26)","Rollenwechsel nach Art. 25 — volle Anbieterpflichten nach Art. 16"),IF(AND(C9="Ja",D9="Ja"),"Anbieterpflichten (Art. 16) UND Betreiberpflichten (Art. 26)",IF(C9="Ja","Anbieterpflichten nach Art. 16",IF(D9="Ja","Betreiberpflichten nach Art. 26",IF(COUNTA(C9:H9)=6,"keine Anbieter-/Betreiberrolle — Einführer-/Händlerpflichten (Art. 23, 24) prüfen","noch offen — bitte alle Fragen beantworten"))))))
B10: =IF(A10="","",IFERROR(INDEX('01_KI-Inventar'!$B$6:$B$65,MATCH(A10,'01_KI-Inventar'!$A$6:$A$65,0)),"")) | I10: =IF(A10="","",IF(OR(C10="Ja",E10="Ja",F10="Ja",G10="Ja",H10="Ja"),IF(D10="Ja","Anbieter und Betreiber","Anbieter"),IF(D10="Ja","Betreiber",IF(COUNTA(C10:H10)=6,"keine Anbieter-/Betreiberrolle","noch offen")))) | J10: =IF(A10="","",IF(OR(E10="Ja",F10="Ja",G10="Ja",H10="Ja"),IF(D10="Ja","Rollenwechsel nach Art. 25 — Anbieterpflichten (Art. 16) UND Betreiberpflichten (Art. 26)","Rollenwechsel nach Art. 25 — volle Anbieterpflichten nach Art. 16"),IF(AND(C10="Ja",D10="Ja"),"Anbieterpflichten (Art. 16) UND Betreiberpflichten (Art. 26)",IF(C10="Ja","Anbieterpflichten nach Art. 16",IF(D10="Ja","Betreiberpflichten nach Art. 26",IF(COUNTA(C10:H10)=6,"keine Anbieter-/Betreiberrolle — Einführer-/Händlerpflichten (Art. 23, 24) prüfen","noch offen — bitte alle Fragen beantworten"))))))
B11: =IF(A11="","",IFERROR(INDEX('01_KI-Inventar'!$B$6:$B$65,MATCH(A11,'01_KI-Inventar'!$A$6:$A$65,0)),"")) | I11: =IF(A11="","",IF(OR(C11="Ja",E11="Ja",F11="Ja",G11="Ja",H11="Ja"),IF(D11="Ja","Anbieter und Betreiber","Anbieter"),IF(D11="Ja","Betreiber",IF(COUNTA(C11:H11)=6,"keine Anbieter-/Betreiberrolle","noch offen")))) | J11: =IF(A11="","",IF(OR(E11="Ja",F11="Ja",G11="Ja",H11="Ja"),IF(D11="Ja","Rollenwechsel nach Art. 25 — Anbieterpflichten (Art. 16) UND Betreiberpflichten (Art. 26)","Rollenwechsel nach Art. 25 — volle Anbieterpflichten nach Art. 16"),IF(AND(C11="Ja",D11="Ja"),"Anbieterpflichten (Art. 16) UND Betreiberpflichten (Art. 26)",IF(C11="Ja","Anbieterpflichten nach Art. 16",IF(D11="Ja","Betreiberpflichten nach Art. 26",IF(COUNTA(C11:H11)=6,"keine Anbieter-/Betreiberrolle — Einführer-/Händlerpflichten (Art. 23, 24) prüfen","noch offen — bitte alle Fragen beantworten"))))))
B12: =IF(A12="","",IFERROR(INDEX('01_KI-Inventar'!$B$6:$B$65,MATCH(A12,'01_KI-Inventar'!$A$6:$A$65,0)),"")) | I12: =IF(A12="","",IF(OR(C12="Ja",E12="Ja",F12="Ja",G12="Ja",H12="Ja"),IF(D12="Ja","Anbieter und Betreiber","Anbieter"),IF(D12="Ja","Betreiber",IF(COUNTA(C12:H12)=6,"keine Anbieter-/Betreiberrolle","noch offen")))) | J12: =IF(A12="","",IF(OR(E12="Ja",F12="Ja",G12="Ja",H12="Ja"),IF(D12="Ja","Rollenwechsel nach Art. 25 — Anbieterpflichten (Art. 16) UND Betreiberpflichten (Art. 26)","Rollenwechsel nach Art. 25 — volle Anbieterpflichten nach Art. 16"),IF(AND(C12="Ja",D12="Ja"),"Anbieterpflichten (Art. 16) UND Betreiberpflichten (Art. 26)",IF(C12="Ja","Anbieterpflichten nach Art. 16",IF(D12="Ja","Betreiberpflichten nach Art. 26",IF(COUNTA(C12:H12)=6,"keine Anbieter-/Betreiberrolle — Einführer-/Händlerpflichten (Art. 23, 24) prüfen","noch offen — bitte alle Fragen beantworten"))))))
B13: =IF(A13="","",IFERROR(INDEX('01_KI-Inventar'!$B$6:$B$65,MATCH(A13,'01_KI-Inventar'!$A$6:$A$65,0)),"")) | I13: =IF(A13="","",IF(OR(C13="Ja",E13="Ja",F13="Ja",G13="Ja",H13="Ja"),IF(D13="Ja","Anbieter und Betreiber","Anbieter"),IF(D13="Ja","Betreiber",IF(COUNTA(C13:H13)=6,"keine Anbieter-/Betreiberrolle","noch offen")))) | J13: =IF(A13="","",IF(OR(E13="Ja",F13="Ja",G13="Ja",H13="Ja"),IF(D13="Ja","Rollenwechsel nach Art. 25 — Anbieterpflichten (Art. 16) UND Betreiberpflichten (Art. 26)","Rollenwechsel nach Art. 25 — volle Anbieterpflichten nach Art. 16"),IF(AND(C13="Ja",D13="Ja"),"Anbieterpflichten (Art. 16) UND Betreiberpflichten (Art. 26)",IF(C13="Ja","Anbieterpflichten nach Art. 16",IF(D13="Ja","Betreiberpflichten nach Art. 26",IF(COUNTA(C13:H13)=6,"keine Anbieter-/Betreiberrolle — Einführer-/Händlerpflichten (Art. 23, 24) prüfen","noch offen — bitte alle Fragen beantworten"))))))
B14: =IF(A14="","",IFERROR(INDEX('01_KI-Inventar'!$B$6:$B$65,MATCH(A14,'01_KI-Inventar'!$A$6:$A$65,0)),"")) | I14: =IF(A14="","",IF(OR(C14="Ja",E14="Ja",F14="Ja",G14="Ja",H14="Ja"),IF(D14="Ja","Anbieter und Betreiber","Anbieter"),IF(D14="Ja","Betreiber",IF(COUNTA(C14:H14)=6,"keine Anbieter-/Betreiberrolle","noch offen")))) | J14: =IF(A14="","",IF(OR(E14="Ja",F14="Ja",G14="Ja",H14="Ja"),IF(D14="Ja","Rollenwechsel nach Art. 25 — Anbieterpflichten (Art. 16) UND Betreiberpflichten (Art. 26)","Rollenwechsel nach Art. 25 — volle Anbieterpflichten nach Art. 16"),IF(AND(C14="Ja",D14="Ja"),"Anbieterpflichten (Art. 16) UND Betreiberpflichten (Art. 26)",IF(C14="Ja","Anbieterpflichten nach Art. 16",IF(D14="Ja","Betreiberpflichten nach Art. 26",IF(COUNTA(C14:H14)=6,"keine Anbieter-/Betreiberrolle — Einführer-/Händlerpflichten (Art. 23, 24) prüfen","noch offen — bitte alle Fragen beantworten"))))))
B15: =IF(A15="","",IFERROR(INDEX('01_KI-Inventar'!$B$6:$B$65,MATCH(A15,'01_KI-Inventar'!$A$6:$A$65,0)),"")) | I15: =IF(A15="","",IF(OR(C15="Ja",E15="Ja",F15="Ja",G15="Ja",H15="Ja"),IF(D15="Ja","Anbieter und Betreiber","Anbieter"),IF(D15="Ja","Betreiber",IF(COUNTA(C15:H15)=6,"keine Anbieter-/Betreiberrolle","noch offen")))) | J15: =IF(A15="","",IF(OR(E15="Ja",F15="Ja",G15="Ja",H15="Ja"),IF(D15="Ja","Rollenwechsel nach Art. 25 — Anbieterpflichten (Art. 16) UND Betreiberpflichten (Art. 26)","Rollenwechsel nach Art. 25 — volle Anbieterpflichten nach Art. 16"),IF(AND(C15="Ja",D15="Ja"),"Anbieterpflichten (Art. 16) UND Betreiberpflichten (Art. 26)",IF(C15="Ja","Anbieterpflichten nach Art. 16",IF(D15="Ja","Betreiberpflichten nach Art. 26",IF(COUNTA(C15:H15)=6,"keine Anbieter-/Betreiberrolle — Einführer-/Händlerpflichten (Art. 23, 24) prüfen","noch offen — bitte alle Fragen beantworten"))))))
B16: =IF(A16="","",IFERROR(INDEX('01_KI-Inventar'!$B$6:$B$65,MATCH(A16,'01_KI-Inventar'!$A$6:$A$65,0)),"")) | I16: =IF(A16="","",IF(OR(C16="Ja",E16="Ja",F16="Ja",G16="Ja",H16="Ja"),IF(D16="Ja","Anbieter und Betreiber","Anbieter"),IF(D16="Ja","Betreiber",IF(COUNTA(C16:H16)=6,"keine Anbieter-/Betreiberrolle","noch offen")))) | J16: =IF(A16="","",IF(OR(E16="Ja",F16="Ja",G16="Ja",H16="Ja"),IF(D16="Ja","Rollenwechsel nach Art. 25 — Anbieterpflichten (Art. 16) UND Betreiberpflichten (Art. 26)","Rollenwechsel nach Art. 25 — volle Anbieterpflichten nach Art. 16"),IF(AND(C16="Ja",D16="Ja"),"Anbieterpflichten (Art. 16) UND Betreiberpflichten (Art. 26)",IF(C16="Ja","Anbieterpflichten nach Art. 16",IF(D16="Ja","Betreiberpflichten nach Art. 26",IF(COUNTA(C16:H16)=6,"keine Anbieter-/Betreiberrolle — Einführer-/Händlerpflichten (Art. 23, 24) prüfen","noch offen — bitte alle Fragen beantworten"))))))
B17: =IF(A17="","",IFERROR(INDEX('01_KI-Inventar'!$B$6:$B$65,MATCH(A17,'01_KI-Inventar'!$A$6:$A$65,0)),"")) | I17: =IF(A17="","",IF(OR(C17="Ja",E17="Ja",F17="Ja",G17="Ja",H17="Ja"),IF(D17="Ja","Anbieter und Betreiber","Anbieter"),IF(D17="Ja","Betreiber",IF(COUNTA(C17:H17)=6,"keine Anbieter-/Betreiberrolle","noch offen")))) | J17: =IF(A17="","",IF(OR(E17="Ja",F17="Ja",G17="Ja",H17="Ja"),IF(D17="Ja","Rollenwechsel nach Art. 25 — Anbieterpflichten (Art. 16) UND Betreiberpflichten (Art. 26)","Rollenwechsel nach Art. 25 — volle Anbieterpflichten nach Art. 16"),IF(AND(C17="Ja",D17="Ja"),"Anbieterpflichten (Art. 16) UND Betreiberpflichten (Art. 26)",IF(C17="Ja","Anbieterpflichten nach Art. 16",IF(D17="Ja","Betreiberpflichten nach Art. 26",IF(COUNTA(C17:H17)=6,"keine Anbieter-/Betreiberrolle — Einführer-/Händlerpflichten (Art. 23, 24) prüfen","noch offen — bitte alle Fragen beantworten"))))))
... B65: =IF(A65="","",IFERROR(INDEX('01_KI-Inventar'!$B$6:$B$65,MATCH(A65,'01_KI-Inventar'!$A$6:$A$65,0)),"")) | I65: =IF(A65="","",IF(OR(C65="Ja",E65="Ja",F65="Ja",G65="Ja",H65="Ja"),IF(D65="Ja","Anbieter und Betreiber","Anbieter"),IF(D65="Ja","Betreiber",IF(COUNTA(C65:H65)=6,"keine Anbieter-/Betreiberrolle","noch offen")))) | J65: =IF(A65="","",IF(OR(E65="Ja",F65="Ja",G65="Ja",H65="Ja"),IF(D65="Ja","Rollenwechsel nach Art. 25 — Anbieterpflichten (Art. 16) UND Betreiberpflichten (Art. 26)","Rollenwechsel nach Art. 25 — volle Anbieterpflichten nach Art. 16"),IF(AND(C65="Ja",D65="Ja"),"Anbieterpflichten (Art. 16) UND Betreiberpflichten (Art. 26)",IF(C65="Ja","Anbieterpflichten nach Art. 16",IF(D65="Ja","Betreiberpflichten nach Art. 26",IF(COUNTA(C65:H65)=6,"keine Anbieter-/Betreiberrolle — Einführer-/Händlerpflichten (Art. 23, 24) prüfen","noch offen — bitte alle Fragen beantworten"))))))

Sheet 03_Risiko-Einstufung
A1: 03 — Risiko-Einstufung
A2: Prüfkette in dieser Reihenfolge: verboten (Art. 5) → Hochrisiko Anhang I (Abschnitt A oder B!) → Hochrisiko Anhang III → Transparenz (Art. 50) → geringes Risiko. Das Ergebnis ist ein automatischer Prüfungsvorschlag — KEINE Freigabeentscheidung und keine Rechtsprüfung.
A5: System-ID | B5: Bezeichnung (autom.) | C5: Verbotene Praktik nach Art. 5? (inkl. NCII/CSAM ab 02.12.2026) | D5: Anhang I: Sicherheitsbauteil eines drittkonformitätsbewerteten Produkts ODER selbst ein solches Produkt? Art. 6 Abs. 1 lit. a und b, Art. 3 Nr. 14 n. F. | E5: Anhang I — Abschnitt A oder B? Art. 2 Abs. 2 n. F. | F5: Konkreter Rechtsakt aus Anhang I (Nummer und Bezeichnung) | G5: Anhang III: Anwendungsbereich? Art. 6 Abs. 2 | H5: Profiling natürlicher Personen? Art. 6 Abs. 3 UAbs. 3 | I5: Ausnahmefilter Art. 6 Abs. 3 erfüllt? (a–d und kein erhebliches Risiko) | J5: Transparenzfall nach Art. 50? | K5: Ergebnis der ersten Einordnung (autom.) keine Freigabeentscheidung | L5: Anwendbar ab (autom.) | M5: Registrierung EU-Datenbank (autom.) | N5: Zusätzlich Art. 50 (autom.) | O5: Juristisch bestätigt? | P5: Status der Einstufung (autom.) | Q5: Begründung / Dokumentation der Bewertung | R5: Geprüft am (festes Datum, manuell) | S5: Geprüft von | T5: Prüfgrundlage (Rechtsstand)
B6: =IF(A6="","",IFERROR(INDEX('01_KI-Inventar'!$B$6:$B$65,MATCH(A6,'01_KI-Inventar'!$A$6:$A$65,0)),"")) | K6: =IF(A6="","",IF(OR(C6="",D6="",G6="",J6="",COUNTIF(C6:D6,"Prüfung offen")>0,COUNTIF(H6:I6,"Prüfung offen")>0,AND(D6="Ja",OR(E6="",E6="noch offen")),AND(G6<>"keiner",OR(H6="",AND(H6<>"Ja",I6="")))),"noch offen — Angaben unvollständig",IF(C6="Ja","VERBOTEN (Art. 5)",IF(AND(D6="Ja",E6="Abschnitt B",G6<>"keiner"),"Hochrisiko Anhang I Abschnitt B UND Anhang III — gesondert prüfen",IF(AND(D6="Ja",E6="Abschnitt B"),"Hochrisiko Anhang I Abschnitt B (Sektorrecht)",IF(AND(D6="Ja",G6<>"keiner"),"Hochrisiko Anhang I Abschnitt A und Anhang III",IF(D6="Ja","Hochrisiko Anhang I Abschnitt A",IF(G6<>"keiner",IF(H6="Ja","Hochrisiko Anhang III",IF(I6="Ja","Kein Hochrisiko (Art. 6 Abs. 3)","Hochrisiko Anhang III")),IF(J6<>"keiner","Transparenzpflicht (Art. 50)","Geringes Risiko"))))))))) | L6: =IF(K6="","",IF(K6="VERBOTEN (Art. 5)","02.02.2025 (NCII/CSAM: 02.12.2026)",IF(LEFT(K6,10)="noch offen","keine Frist — Einstufung zuerst abschließen",IF(K6="Hochrisiko Anhang I Abschnitt B (Sektorrecht)","Kapitel III gilt nicht. Es gelten nur Art. 6 Abs. 1, Art. 60a und Art. 102–112 (Art. 2 Abs. 2 n. F.). Frist und Pflichten folgen aus dem Sektorrecht — bei Maschinen: Anhang III VO (EU) 2023/1230, delegierter Rechtsakt ab 02.08.2028.",IF(K6="Hochrisiko Anhang I Abschnitt B UND Anhang III — gesondert prüfen","Uneinheitlich: Für den Anhang-I-Teil gilt Art. 2 Abs. 2 n. F. (nur Art. 6 Abs. 1, 60a, 102–112), für den Anhang-III-Teil der 02.12.2027. Juristisch klären.",IF(K6="Hochrisiko Anhang I Abschnitt A und Anhang III","02.12.2027 (Anhang III) / 02.08.2028 (Anhang I Abschnitt A) — Planungsannahme",IF(K6="Hochrisiko Anhang I Abschnitt A","02.08.2028 — Planungsannahme; Vorbehalt delegierter Rechtsakte nach Art. 2 Abs. 13 n. F. (bis 02.08.2027)",IF(K6="Hochrisiko Anhang III","02.12.2027 — Planungsannahme",IF(K6="Transparenzpflicht (Art. 50)","02.08.2026",IF(K6="Kein Hochrisiko (Art. 6 Abs. 3)","Registrierung nach Art. 49 Abs. 2; Bewertung VOR Inverkehrbringen dokumentieren","keine besonderen Pflichten aus den hier geprüften Kategorien — Art. 4 und übriges Recht (DSGVO, Arbeitsrecht, Urheberrecht) weiter prüfen")))))))))) | M6: =IF(K6="","",IF(LEFT(K6,10)="noch offen","noch offen",IF(K6="Kein Hochrisiko (Art. 6 Abs. 3)","Ja — Art. 49 Abs. 2 (Anbieter); Bewertung VOR Inverkehrbringen dokumentieren (Art. 6 Abs. 4)",IF(K6="Hochrisiko Anhang I Abschnitt B (Sektorrecht)","Nein — Art. 49 ist nach Art. 2 Abs. 2 n. F. nicht anwendbar",IF(K6="Hochrisiko Anhang I Abschnitt A","Nein — Art. 49 Abs. 1 gilt nur für Anhang III",IF(AND(LEFT(G6,1)="2",ISNUMBER(SEARCH("Anhang III",K6))),"Nein — Registrierung auf nationaler Ebene (Art. 49 Abs. 5)",IF(ISNUMBER(SEARCH("Anhang III",K6)),"Ja — Art. 49 Abs. 1 (Anbieter); Behörden als Betreiber: Art. 49 Abs. 3","Nein"))))))) | N6: =IF(A6="","",IF(K6="VERBOTEN (Art. 5)","entfällt — Einsatz unzulässig",IF(K6="Hochrisiko Anhang I Abschnitt B (Sektorrecht)","Nein — Art. 50 ist nach Art. 2 Abs. 2 n. F. nicht anwendbar",IF(AND(J6<>"",J6<>"keiner"),"Ja — Art. 50 gilt zusätzlich ab 02.08.2026","Nein")))) | P6: =IF(K6="","",IF(LEFT(K6,10)="noch offen","Prüfung unvollständig",IF(O6="Ja","Einstufung bestätigt",IF(O6="Nein","Juristische Prüfung erforderlich","Arbeitsannahme — nicht bestätigt"))))
B7: =IF(A7="","",IFERROR(INDEX('01_KI-Inventar'!$B$6:$B$65,MATCH(A7,'01_KI-Inventar'!$A$6:$A$65,0)),"")) | K7: =IF(A7="","",IF(OR(C7="",D7="",G7="",J7="",COUNTIF(C7:D7,"Prüfung offen")>0,COUNTIF(H7:I7,"Prüfung offen")>0,AND(D7="Ja",OR(E7="",E7="noch offen")),AND(G7<>"keiner",OR(H7="",AND(H7<>"Ja",I7="")))),"noch offen — Angaben unvollständig",IF(C7="Ja","VERBOTEN (Art. 5)",IF(AND(D7="Ja",E7="Abschnitt B",G7<>"keiner"),"Hochrisiko Anhang I Abschnitt B UND Anhang III — gesondert prüfen",IF(AND(D7="Ja",E7="Abschnitt B"),"Hochrisiko Anhang I Abschnitt B (Sektorrecht)",IF(AND(D7="Ja",G7<>"keiner"),"Hochrisiko Anhang I Abschnitt A und Anhang III",IF(D7="Ja","Hochrisiko Anhang I Abschnitt A",IF(G7<>"keiner",IF(H7="Ja","Hochrisiko Anhang III",IF(I7="Ja","Kein Hochrisiko (Art. 6 Abs. 3)","Hochrisiko Anhang III")),IF(J7<>"keiner","Transparenzpflicht (Art. 50)","Geringes Risiko"))))))))) | L7: =IF(K7="","",IF(K7="VERBOTEN (Art. 5)","02.02.2025 (NCII/CSAM: 02.12.2026)",IF(LEFT(K7,10)="noch offen","keine Frist — Einstufung zuerst abschließen",IF(K7="Hochrisiko Anhang I Abschnitt B (Sektorrecht)","Kapitel III gilt nicht. Es gelten nur Art. 6 Abs. 1, Art. 60a und Art. 102–112 (Art. 2 Abs. 2 n. F.). Frist und Pflichten folgen aus dem Sektorrecht — bei Maschinen: Anhang III VO (EU) 2023/1230, delegierter Rechtsakt ab 02.08.2028.",IF(K7="Hochrisiko Anhang I Abschnitt B UND Anhang III — gesondert prüfen","Uneinheitlich: Für den Anhang-I-Teil gilt Art. 2 Abs. 2 n. F. (nur Art. 6 Abs. 1, 60a, 102–112), für den Anhang-III-Teil der 02.12.2027. Juristisch klären.",IF(K7="Hochrisiko Anhang I Abschnitt A und Anhang III","02.12.2027 (Anhang III) / 02.08.2028 (Anhang I Abschnitt A) — Planungsannahme",IF(K7="Hochrisiko Anhang I Abschnitt A","02.08.2028 — Planungsannahme; Vorbehalt delegierter Rechtsakte nach Art. 2 Abs. 13 n. F. (bis 02.08.2027)",IF(K7="Hochrisiko Anhang III","02.12.2027 — Planungsannahme",IF(K7="Transparenzpflicht (Art. 50)","02.08.2026",IF(K7="Kein Hochrisiko (Art. 6 Abs. 3)","Registrierung nach Art. 49 Abs. 2; Bewertung VOR Inverkehrbringen dokumentieren","keine besonderen Pflichten aus den hier geprüften Kategorien — Art. 4 und übriges Recht (DSGVO, Arbeitsrecht, Urheberrecht) weiter prüfen")))))))))) | M7: =IF(K7="","",IF(LEFT(K7,10)="noch offen","noch offen",IF(K7="Kein Hochrisiko (Art. 6 Abs. 3)","Ja — Art. 49 Abs. 2 (Anbieter); Bewertung VOR Inverkehrbringen dokumentieren (Art. 6 Abs. 4)",IF(K7="Hochrisiko Anhang I Abschnitt B (Sektorrecht)","Nein — Art. 49 ist nach Art. 2 Abs. 2 n. F. nicht anwendbar",IF(K7="Hochrisiko Anhang I Abschnitt A","Nein — Art. 49 Abs. 1 gilt nur für Anhang III",IF(AND(LEFT(G7,1)="2",ISNUMBER(SEARCH("Anhang III",K7))),"Nein — Registrierung auf nationaler Ebene (Art. 49 Abs. 5)",IF(ISNUMBER(SEARCH("Anhang III",K7)),"Ja — Art. 49 Abs. 1 (Anbieter); Behörden als Betreiber: Art. 49 Abs. 3","Nein"))))))) | N7: =IF(A7="","",IF(K7="VERBOTEN (Art. 5)","entfällt — Einsatz unzulässig",IF(K7="Hochrisiko Anhang I Abschnitt B (Sektorrecht)","Nein — Art. 50 ist nach Art. 2 Abs. 2 n. F. nicht anwendbar",IF(AND(J7<>"",J7<>"keiner"),"Ja — Art. 50 gilt zusätzlich ab 02.08.2026","Nein")))) | P7: =IF(K7="","",IF(LEFT(K7,10)="noch offen","Prüfung unvollständig",IF(O7="Ja","Einstufung bestätigt",IF(O7="Nein","Juristische Prüfung erforderlich","Arbeitsannahme — nicht bestätigt"))))
B8: =IF(A8="","",IFERROR(INDEX('01_KI-Inventar'!$B$6:$B$65,MATCH(A8,'01_KI-Inventar'!$A$6:$A$65,0)),"")) | K8: =IF(A8="","",IF(OR(C8="",D8="",G8="",J8="",COUNTIF(C8:D8,"Prüfung offen")>0,COUNTIF(H8:I8,"Prüfung offen")>0,AND(D8="Ja",OR(E8="",E8="noch offen")),AND(G8<>"keiner",OR(H8="",AND(H8<>"Ja",I8="")))),"noch offen — Angaben unvollständig",IF(C8="Ja","VERBOTEN (Art. 5)",IF(AND(D8="Ja",E8="Abschnitt B",G8<>"keiner"),"Hochrisiko Anhang I Abschnitt B UND Anhang III — gesondert prüfen",IF(AND(D8="Ja",E8="Abschnitt B"),"Hochrisiko Anhang I Abschnitt B (Sektorrecht)",IF(AND(D8="Ja",G8<>"keiner"),"Hochrisiko Anhang I Abschnitt A und Anhang III",IF(D8="Ja","Hochrisiko Anhang I Abschnitt A",IF(G8<>"keiner",IF(H8="Ja","Hochrisiko Anhang III",IF(I8="Ja","Kein Hochrisiko (Art. 6 Abs. 3)","Hochrisiko Anhang III")),IF(J8<>"keiner","Transparenzpflicht (Art. 50)","Geringes Risiko"))))))))) | L8: =IF(K8="","",IF(K8="VERBOTEN (Art. 5)","02.02.2025 (NCII/CSAM: 02.12.2026)",IF(LEFT(K8,10)="noch offen","keine Frist — Einstufung zuerst abschließen",IF(K8="Hochrisiko Anhang I Abschnitt B (Sektorrecht)","Kapitel III gilt nicht. Es gelten nur Art. 6 Abs. 1, Art. 60a und Art. 102–112 (Art. 2 Abs. 2 n. F.). Frist und Pflichten folgen aus dem Sektorrecht — bei Maschinen: Anhang III VO (EU) 2023/1230, delegierter Rechtsakt ab 02.08.2028.",IF(K8="Hochrisiko Anhang I Abschnitt B UND Anhang III — gesondert prüfen","Uneinheitlich: Für den Anhang-I-Teil gilt Art. 2 Abs. 2 n. F. (nur Art. 6 Abs. 1, 60a, 102–112), für den Anhang-III-Teil der 02.12.2027. Juristisch klären.",IF(K8="Hochrisiko Anhang I Abschnitt A und Anhang III","02.12.2027 (Anhang III) / 02.08.2028 (Anhang I Abschnitt A) — Planungsannahme",IF(K8="Hochrisiko Anhang I Abschnitt A","02.08.2028 — Planungsannahme; Vorbehalt delegierter Rechtsakte nach Art. 2 Abs. 13 n. F. (bis 02.08.2027)",IF(K8="Hochrisiko Anhang III","02.12.2027 — Planungsannahme",IF(K8="Transparenzpflicht (Art. 50)","02.08.2026",IF(K8="Kein Hochrisiko (Art. 6 Abs. 3)","Registrierung nach Art. 49 Abs. 2; Bewertung VOR Inverkehrbringen dokumentieren","keine besonderen Pflichten aus den hier geprüften Kategorien — Art. 4 und übriges Recht (DSGVO, Arbeitsrecht, Urheberrecht) weiter prüfen")))))))))) | M8: =IF(K8="","",IF(LEFT(K8,10)="noch offen","noch offen",IF(K8="Kein Hochrisiko (Art. 6 Abs. 3)","Ja — Art. 49 Abs. 2 (Anbieter); Bewertung VOR Inverkehrbringen dokumentieren (Art. 6 Abs. 4)",IF(K8="Hochrisiko Anhang I Abschnitt B (Sektorrecht)","Nein — Art. 49 ist nach Art. 2 Abs. 2 n. F. nicht anwendbar",IF(K8="Hochrisiko Anhang I Abschnitt A","Nein — Art. 49 Abs. 1 gilt nur für Anhang III",IF(AND(LEFT(G8,1)="2",ISNUMBER(SEARCH("Anhang III",K8))),"Nein — Registrierung auf nationaler Ebene (Art. 49 Abs. 5)",IF(ISNUMBER(SEARCH("Anhang III",K8)),"Ja — Art. 49 Abs. 1 (Anbieter); Behörden als Betreiber: Art. 49 Abs. 3","Nein"))))))) | N8: =IF(A8="","",IF(K8="VERBOTEN (Art. 5)","entfällt — Einsatz unzulässig",IF(K8="Hochrisiko Anhang I Abschnitt B (Sektorrecht)","Nein — Art. 50 ist nach Art. 2 Abs. 2 n. F. nicht anwendbar",IF(AND(J8<>"",J8<>"keiner"),"Ja — Art. 50 gilt zusätzlich ab 02.08.2026","Nein")))) | P8: =IF(K8="","",IF(LEFT(K8,10)="noch offen","Prüfung unvollständig",IF(O8="Ja","Einstufung bestätigt",IF(O8="Nein","Juristische Prüfung erforderlich","Arbeitsannahme — nicht bestätigt"))))
B9: =IF(A9="","",IFERROR(INDEX('01_KI-Inventar'!$B$6:$B$65,MATCH(A9,'01_KI-Inventar'!$A$6:$A$65,0)),"")) | K9: =IF(A9="","",IF(OR(C9="",D9="",G9="",J9="",COUNTIF(C9:D9,"Prüfung offen")>0,COUNTIF(H9:I9,"Prüfung offen")>0,AND(D9="Ja",OR(E9="",E9="noch offen")),AND(G9<>"keiner",OR(H9="",AND(H9<>"Ja",I9="")))),"noch offen — Angaben unvollständig",IF(C9="Ja","VERBOTEN (Art. 5)",IF(AND(D9="Ja",E9="Abschnitt B",G9<>"keiner"),"Hochrisiko Anhang I Abschnitt B UND Anhang III — gesondert prüfen",IF(AND(D9="Ja",E9="Abschnitt B"),"Hochrisiko Anhang I Abschnitt B (Sektorrecht)",IF(AND(D9="Ja",G9<>"keiner"),"Hochrisiko Anhang I Abschnitt A und Anhang III",IF(D9="Ja","Hochrisiko Anhang I Abschnitt A",IF(G9<>"keiner",IF(H9="Ja","Hochrisiko Anhang III",IF(I9="Ja","Kein Hochrisiko (Art. 6 Abs. 3)","Hochrisiko Anhang III")),IF(J9<>"keiner","Transparenzpflicht (Art. 50)","Geringes Risiko"))))))))) | L9: =IF(K9="","",IF(K9="VERBOTEN (Art. 5)","02.02.2025 (NCII/CSAM: 02.12.2026)",IF(LEFT(K9,10)="noch offen","keine Frist — Einstufung zuerst abschließen",IF(K9="Hochrisiko Anhang I Abschnitt B (Sektorrecht)","Kapitel III gilt nicht. Es gelten nur Art. 6 Abs. 1, Art. 60a und Art. 102–112 (Art. 2 Abs. 2 n. F.). Frist und Pflichten folgen aus dem Sektorrecht — bei Maschinen: Anhang III VO (EU) 2023/1230, delegierter Rechtsakt ab 02.08.2028.",IF(K9="Hochrisiko Anhang I Abschnitt B UND Anhang III — gesondert prüfen","Uneinheitlich: Für den Anhang-I-Teil gilt Art. 2 Abs. 2 n. F. (nur Art. 6 Abs. 1, 60a, 102–112), für den Anhang-III-Teil der 02.12.2027. Juristisch klären.",IF(K9="Hochrisiko Anhang I Abschnitt A und Anhang III","02.12.2027 (Anhang III) / 02.08.2028 (Anhang I Abschnitt A) — Planungsannahme",IF(K9="Hochrisiko Anhang I Abschnitt A","02.08.2028 — Planungsannahme; Vorbehalt delegierter Rechtsakte nach Art. 2 Abs. 13 n. F. (bis 02.08.2027)",IF(K9="Hochrisiko Anhang III","02.12.2027 — Planungsannahme",IF(K9="Transparenzpflicht (Art. 50)","02.08.2026",IF(K9="Kein Hochrisiko (Art. 6 Abs. 3)","Registrierung nach Art. 49 Abs. 2; Bewertung VOR Inverkehrbringen dokumentieren","keine besonderen Pflichten aus den hier geprüften Kategorien — Art. 4 und übriges Recht (DSGVO, Arbeitsrecht, Urheberrecht) weiter prüfen")))))))))) | M9: =IF(K9="","",IF(LEFT(K9,10)="noch offen","noch offen",IF(K9="Kein Hochrisiko (Art. 6 Abs. 3)","Ja — Art. 49 Abs. 2 (Anbieter); Bewertung VOR Inverkehrbringen dokumentieren (Art. 6 Abs. 4)",IF(K9="Hochrisiko Anhang I Abschnitt B (Sektorrecht)","Nein — Art. 49 ist nach Art. 2 Abs. 2 n. F. nicht anwendbar",IF(K9="Hochrisiko Anhang I Abschnitt A","Nein — Art. 49 Abs. 1 gilt nur für Anhang III",IF(AND(LEFT(G9,1)="2",ISNUMBER(SEARCH("Anhang III",K9))),"Nein — Registrierung auf nationaler Ebene (Art. 49 Abs. 5)",IF(ISNUMBER(SEARCH("Anhang III",K9)),"Ja — Art. 49 Abs. 1 (Anbieter); Behörden als Betreiber: Art. 49 Abs. 3","Nein"))))))) | N9: =IF(A9="","",IF(K9="VERBOTEN (Art. 5)","entfällt — Einsatz unzulässig",IF(K9="Hochrisiko Anhang I Abschnitt B (Sektorrecht)","Nein — Art. 50 ist nach Art. 2 Abs. 2 n. F. nicht anwendbar",IF(AND(J9<>"",J9<>"keiner"),"Ja — Art. 50 gilt zusätzlich ab 02.08.2026","Nein")))) | P9: =IF(K9="","",IF(LEFT(K9,10)="noch offen","Prüfung unvollständig",IF(O9="Ja","Einstufung bestätigt",IF(O9="Nein","Juristische Prüfung erforderlich","Arbeitsannahme — nicht bestätigt"))))
B10: =IF(A10="","",IFERROR(INDEX('01_KI-Inventar'!$B$6:$B$65,MATCH(A10,'01_KI-Inventar'!$A$6:$A$65,0)),"")) | K10: =IF(A10="","",IF(OR(C10="",D10="",G10="",J10="",COUNTIF(C10:D10,"Prüfung offen")>0,COUNTIF(H10:I10,"Prüfung offen")>0,AND(D10="Ja",OR(E10="",E10="noch offen")),AND(G10<>"keiner",OR(H10="",AND(H10<>"Ja",I10="")))),"noch offen — Angaben unvollständig",IF(C10="Ja","VERBOTEN (Art. 5)",IF(AND(D10="Ja",E10="Abschnitt B",G10<>"keiner"),"Hochrisiko Anhang I Abschnitt B UND Anhang III — gesondert prüfen",IF(AND(D10="Ja",E10="Abschnitt B"),"Hochrisiko Anhang I Abschnitt B (Sektorrecht)",IF(AND(D10="Ja",G10<>"keiner"),"Hochrisiko Anhang I Abschnitt A und Anhang III",IF(D10="Ja","Hochrisiko Anhang I Abschnitt A",IF(G10<>"keiner",IF(H10="Ja","Hochrisiko Anhang III",IF(I10="Ja","Kein Hochrisiko (Art. 6 Abs. 3)","Hochrisiko Anhang III")),IF(J10<>"keiner","Transparenzpflicht (Art. 50)","Geringes Risiko"))))))))) | L10: =IF(K10="","",IF(K10="VERBOTEN (Art. 5)","02.02.2025 (NCII/CSAM: 02.12.2026)",IF(LEFT(K10,10)="noch offen","keine Frist — Einstufung zuerst abschließen",IF(K10="Hochrisiko Anhang I Abschnitt B (Sektorrecht)","Kapitel III gilt nicht. Es gelten nur Art. 6 Abs. 1, Art. 60a und Art. 102–112 (Art. 2 Abs. 2 n. F.). Frist und Pflichten folgen aus dem Sektorrecht — bei Maschinen: Anhang III VO (EU) 2023/1230, delegierter Rechtsakt ab 02.08.2028.",IF(K10="Hochrisiko Anhang I Abschnitt B UND Anhang III — gesondert prüfen","Uneinheitlich: Für den Anhang-I-Teil gilt Art. 2 Abs. 2 n. F. (nur Art. 6 Abs. 1, 60a, 102–112), für den Anhang-III-Teil der 02.12.2027. Juristisch klären.",IF(K10="Hochrisiko Anhang I Abschnitt A und Anhang III","02.12.2027 (Anhang III) / 02.08.2028 (Anhang I Abschnitt A) — Planungsannahme",IF(K10="Hochrisiko Anhang I Abschnitt A","02.08.2028 — Planungsannahme; Vorbehalt delegierter Rechtsakte nach Art. 2 Abs. 13 n. F. (bis 02.08.2027)",IF(K10="Hochrisiko Anhang III","02.12.2027 — Planungsannahme",IF(K10="Transparenzpflicht (Art. 50)","02.08.2026",IF(K10="Kein Hochrisiko (Art. 6 Abs. 3)","Registrierung nach Art. 49 Abs. 2; Bewertung VOR Inverkehrbringen dokumentieren","keine besonderen Pflichten aus den hier geprüften Kategorien — Art. 4 und übriges Recht (DSGVO, Arbeitsrecht, Urheberrecht) weiter prüfen")))))))))) | M10: =IF(K10="","",IF(LEFT(K10,10)="noch offen","noch offen",IF(K10="Kein Hochrisiko (Art. 6 Abs. 3)","Ja — Art. 49 Abs. 2 (Anbieter); Bewertung VOR Inverkehrbringen dokumentieren (Art. 6 Abs. 4)",IF(K10="Hochrisiko Anhang I Abschnitt B (Sektorrecht)","Nein — Art. 49 ist nach Art. 2 Abs. 2 n. F. nicht anwendbar",IF(K10="Hochrisiko Anhang I Abschnitt A","Nein — Art. 49 Abs. 1 gilt nur für Anhang III",IF(AND(LEFT(G10,1)="2",ISNUMBER(SEARCH("Anhang III",K10))),"Nein — Registrierung auf nationaler Ebene (Art. 49 Abs. 5)",IF(ISNUMBER(SEARCH("Anhang III",K10)),"Ja — Art. 49 Abs. 1 (Anbieter); Behörden als Betreiber: Art. 49 Abs. 3","Nein"))))))) | N10: =IF(A10="","",IF(K10="VERBOTEN (Art. 5)","entfällt — Einsatz unzulässig",IF(K10="Hochrisiko Anhang I Abschnitt B (Sektorrecht)","Nein — Art. 50 ist nach Art. 2 Abs. 2 n. F. nicht anwendbar",IF(AND(J10<>"",J10<>"keiner"),"Ja — Art. 50 gilt zusätzlich ab 02.08.2026","Nein")))) | P10: =IF(K10="","",IF(LEFT(K10,10)="noch offen","Prüfung unvollständig",IF(O10="Ja","Einstufung bestätigt",IF(O10="Nein","Juristische Prüfung erforderlich","Arbeitsannahme — nicht bestätigt"))))
B11: =IF(A11="","",IFERROR(INDEX('01_KI-Inventar'!$B$6:$B$65,MATCH(A11,'01_KI-Inventar'!$A$6:$A$65,0)),"")) | K11: =IF(A11="","",IF(OR(C11="",D11="",G11="",J11="",COUNTIF(C11:D11,"Prüfung offen")>0,COUNTIF(H11:I11,"Prüfung offen")>0,AND(D11="Ja",OR(E11="",E11="noch offen")),AND(G11<>"keiner",OR(H11="",AND(H11<>"Ja",I11="")))),"noch offen — Angaben unvollständig",IF(C11="Ja","VERBOTEN (Art. 5)",IF(AND(D11="Ja",E11="Abschnitt B",G11<>"keiner"),"Hochrisiko Anhang I Abschnitt B UND Anhang III — gesondert prüfen",IF(AND(D11="Ja",E11="Abschnitt B"),"Hochrisiko Anhang I Abschnitt B (Sektorrecht)",IF(AND(D11="Ja",G11<>"keiner"),"Hochrisiko Anhang I Abschnitt A und Anhang III",IF(D11="Ja","Hochrisiko Anhang I Abschnitt A",IF(G11<>"keiner",IF(H11="Ja","Hochrisiko Anhang III",IF(I11="Ja","Kein Hochrisiko (Art. 6 Abs. 3)","Hochrisiko Anhang III")),IF(J11<>"keiner","Transparenzpflicht (Art. 50)","Geringes Risiko"))))))))) | L11: =IF(K11="","",IF(K11="VERBOTEN (Art. 5)","02.02.2025 (NCII/CSAM: 02.12.2026)",IF(LEFT(K11,10)="noch offen","keine Frist — Einstufung zuerst abschließen",IF(K11="Hochrisiko Anhang I Abschnitt B (Sektorrecht)","Kapitel III gilt nicht. Es gelten nur Art. 6 Abs. 1, Art. 60a und Art. 102–112 (Art. 2 Abs. 2 n. F.). Frist und Pflichten folgen aus dem Sektorrecht — bei Maschinen: Anhang III VO (EU) 2023/1230, delegierter Rechtsakt ab 02.08.2028.",IF(K11="Hochrisiko Anhang I Abschnitt B UND Anhang III — gesondert prüfen","Uneinheitlich: Für den Anhang-I-Teil gilt Art. 2 Abs. 2 n. F. (nur Art. 6 Abs. 1, 60a, 102–112), für den Anhang-III-Teil der 02.12.2027. Juristisch klären.",IF(K11="Hochrisiko Anhang I Abschnitt A und Anhang III","02.12.2027 (Anhang III) / 02.08.2028 (Anhang I Abschnitt A) — Planungsannahme",IF(K11="Hochrisiko Anhang I Abschnitt A","02.08.2028 — Planungsannahme; Vorbehalt delegierter Rechtsakte nach Art. 2 Abs. 13 n. F. (bis 02.08.2027)",IF(K11="Hochrisiko Anhang III","02.12.2027 — Planungsannahme",IF(K11="Transparenzpflicht (Art. 50)","02.08.2026",IF(K11="Kein Hochrisiko (Art. 6 Abs. 3)","Registrierung nach Art. 49 Abs. 2; Bewertung VOR Inverkehrbringen dokumentieren","keine besonderen Pflichten aus den hier geprüften Kategorien — Art. 4 und übriges Recht (DSGVO, Arbeitsrecht, Urheberrecht) weiter prüfen")))))))))) | M11: =IF(K11="","",IF(LEFT(K11,10)="noch offen","noch offen",IF(K11="Kein Hochrisiko (Art. 6 Abs. 3)","Ja — Art. 49 Abs. 2 (Anbieter); Bewertung VOR Inverkehrbringen dokumentieren (Art. 6 Abs. 4)",IF(K11="Hochrisiko Anhang I Abschnitt B (Sektorrecht)","Nein — Art. 49 ist nach Art. 2 Abs. 2 n. F. nicht anwendbar",IF(K11="Hochrisiko Anhang I Abschnitt A","Nein — Art. 49 Abs. 1 gilt nur für Anhang III",IF(AND(LEFT(G11,1)="2",ISNUMBER(SEARCH("Anhang III",K11))),"Nein — Registrierung auf nationaler Ebene (Art. 49 Abs. 5)",IF(ISNUMBER(SEARCH("Anhang III",K11)),"Ja — Art. 49 Abs. 1 (Anbieter); Behörden als Betreiber: Art. 49 Abs. 3","Nein"))))))) | N11: =IF(A11="","",IF(K11="VERBOTEN (Art. 5)","entfällt — Einsatz unzulässig",IF(K11="Hochrisiko Anhang I Abschnitt B (Sektorrecht)","Nein — Art. 50 ist nach Art. 2 Abs. 2 n. F. nicht anwendbar",IF(AND(J11<>"",J11<>"keiner"),"Ja — Art. 50 gilt zusätzlich ab 02.08.2026","Nein")))) | P11: =IF(K11="","",IF(LEFT(K11,10)="noch offen","Prüfung unvollständig",IF(O11="Ja","Einstufung bestätigt",IF(O11="Nein","Juristische Prüfung erforderlich","Arbeitsannahme — nicht bestätigt"))))
B12: =IF(A12="","",IFERROR(INDEX('01_KI-Inventar'!$B$6:$B$65,MATCH(A12,'01_KI-Inventar'!$A$6:$A$65,0)),"")) | K12: =IF(A12="","",IF(OR(C12="",D12="",G12="",J12="",COUNTIF(C12:D12,"Prüfung offen")>0,COUNTIF(H12:I12,"Prüfung offen")>0,AND(D12="Ja",OR(E12="",E12="noch offen")),AND(G12<>"keiner",OR(H12="",AND(H12<>"Ja",I12="")))),"noch offen — Angaben unvollständig",IF(C12="Ja","VERBOTEN (Art. 5)",IF(AND(D12="Ja",E12="Abschnitt B",G12<>"keiner"),"Hochrisiko Anhang I Abschnitt B UND Anhang III — gesondert prüfen",IF(AND(D12="Ja",E12="Abschnitt B"),"Hochrisiko Anhang I Abschnitt B (Sektorrecht)",IF(AND(D12="Ja",G12<>"keiner"),"Hochrisiko Anhang I Abschnitt A und Anhang III",IF(D12="Ja","Hochrisiko Anhang I Abschnitt A",IF(G12<>"keiner",IF(H12="Ja","Hochrisiko Anhang III",IF(I12="Ja","Kein Hochrisiko (Art. 6 Abs. 3)","Hochrisiko Anhang III")),IF(J12<>"keiner","Transparenzpflicht (Art. 50)","Geringes Risiko"))))))))) | L12: =IF(K12="","",IF(K12="VERBOTEN (Art. 5)","02.02.2025 (NCII/CSAM: 02.12.2026)",IF(LEFT(K12,10)="noch offen","keine Frist — Einstufung zuerst abschließen",IF(K12="Hochrisiko Anhang I Abschnitt B (Sektorrecht)","Kapitel III gilt nicht. Es gelten nur Art. 6 Abs. 1, Art. 60a und Art. 102–112 (Art. 2 Abs. 2 n. F.). Frist und Pflichten folgen aus dem Sektorrecht — bei Maschinen: Anhang III VO (EU) 2023/1230, delegierter Rechtsakt ab 02.08.2028.",IF(K12="Hochrisiko Anhang I Abschnitt B UND Anhang III — gesondert prüfen","Uneinheitlich: Für den Anhang-I-Teil gilt Art. 2 Abs. 2 n. F. (nur Art. 6 Abs. 1, 60a, 102–112), für den Anhang-III-Teil der 02.12.2027. Juristisch klären.",IF(K12="Hochrisiko Anhang I Abschnitt A und Anhang III","02.12.2027 (Anhang III) / 02.08.2028 (Anhang I Abschnitt A) — Planungsannahme",IF(K12="Hochrisiko Anhang I Abschnitt A","02.08.2028 — Planungsannahme; Vorbehalt delegierter Rechtsakte nach Art. 2 Abs. 13 n. F. (bis 02.08.2027)",IF(K12="Hochrisiko Anhang III","02.12.2027 — Planungsannahme",IF(K12="Transparenzpflicht (Art. 50)","02.08.2026",IF(K12="Kein Hochrisiko (Art. 6 Abs. 3)","Registrierung nach Art. 49 Abs. 2; Bewertung VOR Inverkehrbringen dokumentieren","keine besonderen Pflichten aus den hier geprüften Kategorien — Art. 4 und übriges Recht (DSGVO, Arbeitsrecht, Urheberrecht) weiter prüfen")))))))))) | M12: =IF(K12="","",IF(LEFT(K12,10)="noch offen","noch offen",IF(K12="Kein Hochrisiko (Art. 6 Abs. 3)","Ja — Art. 49 Abs. 2 (Anbieter); Bewertung VOR Inverkehrbringen dokumentieren (Art. 6 Abs. 4)",IF(K12="Hochrisiko Anhang I Abschnitt B (Sektorrecht)","Nein — Art. 49 ist nach Art. 2 Abs. 2 n. F. nicht anwendbar",IF(K12="Hochrisiko Anhang I Abschnitt A","Nein — Art. 49 Abs. 1 gilt nur für Anhang III",IF(AND(LEFT(G12,1)="2",ISNUMBER(SEARCH("Anhang III",K12))),"Nein — Registrierung auf nationaler Ebene (Art. 49 Abs. 5)",IF(ISNUMBER(SEARCH("Anhang III",K12)),"Ja — Art. 49 Abs. 1 (Anbieter); Behörden als Betreiber: Art. 49 Abs. 3","Nein"))))))) | N12: =IF(A12="","",IF(K12="VERBOTEN (Art. 5)","entfällt — Einsatz unzulässig",IF(K12="Hochrisiko Anhang I Abschnitt B (Sektorrecht)","Nein — Art. 50 ist nach Art. 2 Abs. 2 n. F. nicht anwendbar",IF(AND(J12<>"",J12<>"keiner"),"Ja — Art. 50 gilt zusätzlich ab 02.08.2026","Nein")))) | P12: =IF(K12="","",IF(LEFT(K12,10)="noch offen","Prüfung unvollständig",IF(O12="Ja","Einstufung bestätigt",IF(O12="Nein","Juristische Prüfung erforderlich","Arbeitsannahme — nicht bestätigt"))))
B13: =IF(A13="","",IFERROR(INDEX('01_KI-Inventar'!$B$6:$B$65,MATCH(A13,'01_KI-Inventar'!$A$6:$A$65,0)),"")) | K13: =IF(A13="","",IF(OR(C13="",D13="",G13="",J13="",COUNTIF(C13:D13,"Prüfung offen")>0,COUNTIF(H13:I13,"Prüfung offen")>0,AND(D13="Ja",OR(E13="",E13="noch offen")),AND(G13<>"keiner",OR(H13="",AND(H13<>"Ja",I13="")))),"noch offen — Angaben unvollständig",IF(C13="Ja","VERBOTEN (Art. 5)",IF(AND(D13="Ja",E13="Abschnitt B",G13<>"keiner"),"Hochrisiko Anhang I Abschnitt B UND Anhang III — gesondert prüfen",IF(AND(D13="Ja",E13="Abschnitt B"),"Hochrisiko Anhang I Abschnitt B (Sektorrecht)",IF(AND(D13="Ja",G13<>"keiner"),"Hochrisiko Anhang I Abschnitt A und Anhang III",IF(D13="Ja","Hochrisiko Anhang I Abschnitt A",IF(G13<>"keiner",IF(H13="Ja","Hochrisiko Anhang III",IF(I13="Ja","Kein Hochrisiko (Art. 6 Abs. 3)","Hochrisiko Anhang III")),IF(J13<>"keiner","Transparenzpflicht (Art. 50)","Geringes Risiko"))))))))) | L13: =IF(K13="","",IF(K13="VERBOTEN (Art. 5)","02.02.2025 (NCII/CSAM: 02.12.2026)",IF(LEFT(K13,10)="noch offen","keine Frist — Einstufung zuerst abschließen",IF(K13="Hochrisiko Anhang I Abschnitt B (Sektorrecht)","Kapitel III gilt nicht. Es gelten nur Art. 6 Abs. 1, Art. 60a und Art. 102–112 (Art. 2 Abs. 2 n. F.). Frist und Pflichten folgen aus dem Sektorrecht — bei Maschinen: Anhang III VO (EU) 2023/1230, delegierter Rechtsakt ab 02.08.2028.",IF(K13="Hochrisiko Anhang I Abschnitt B UND Anhang III — gesondert prüfen","Uneinheitlich: Für den Anhang-I-Teil gilt Art. 2 Abs. 2 n. F. (nur Art. 6 Abs. 1, 60a, 102–112), für den Anhang-III-Teil der 02.12.2027. Juristisch klären.",IF(K13="Hochrisiko Anhang I Abschnitt A und Anhang III","02.12.2027 (Anhang III) / 02.08.2028 (Anhang I Abschnitt A) — Planungsannahme",IF(K13="Hochrisiko Anhang I Abschnitt A","02.08.2028 — Planungsannahme; Vorbehalt delegierter Rechtsakte nach Art. 2 Abs. 13 n. F. (bis 02.08.2027)",IF(K13="Hochrisiko Anhang III","02.12.2027 — Planungsannahme",IF(K13="Transparenzpflicht (Art. 50)","02.08.2026",IF(K13="Kein Hochrisiko (Art. 6 Abs. 3)","Registrierung nach Art. 49 Abs. 2; Bewertung VOR Inverkehrbringen dokumentieren","keine besonderen Pflichten aus den hier geprüften Kategorien — Art. 4 und übriges Recht (DSGVO, Arbeitsrecht, Urheberrecht) weiter prüfen")))))))))) | M13: =IF(K13="","",IF(LEFT(K13,10)="noch offen","noch offen",IF(K13="Kein Hochrisiko (Art. 6 Abs. 3)","Ja — Art. 49 Abs. 2 (Anbieter); Bewertung VOR Inverkehrbringen dokumentieren (Art. 6 Abs. 4)",IF(K13="Hochrisiko Anhang I Abschnitt B (Sektorrecht)","Nein — Art. 49 ist nach Art. 2 Abs. 2 n. F. nicht anwendbar",IF(K13="Hochrisiko Anhang I Abschnitt A","Nein — Art. 49 Abs. 1 gilt nur für Anhang III",IF(AND(LEFT(G13,1)="2",ISNUMBER(SEARCH("Anhang III",K13))),"Nein — Registrierung auf nationaler Ebene (Art. 49 Abs. 5)",IF(ISNUMBER(SEARCH("Anhang III",K13)),"Ja — Art. 49 Abs. 1 (Anbieter); Behörden als Betreiber: Art. 49 Abs. 3","Nein"))))))) | N13: =IF(A13="","",IF(K13="VERBOTEN (Art. 5)","entfällt — Einsatz unzulässig",IF(K13="Hochrisiko Anhang I Abschnitt B (Sektorrecht)","Nein — Art. 50 ist nach Art. 2 Abs. 2 n. F. nicht anwendbar",IF(AND(J13<>"",J13<>"keiner"),"Ja — Art. 50 gilt zusätzlich ab 02.08.2026","Nein")))) | P13: =IF(K13="","",IF(LEFT(K13,10)="noch offen","Prüfung unvollständig",IF(O13="Ja","Einstufung bestätigt",IF(O13="Nein","Juristische Prüfung erforderlich","Arbeitsannahme — nicht bestätigt"))))
B14: =IF(A14="","",IFERROR(INDEX('01_KI-Inventar'!$B$6:$B$65,MATCH(A14,'01_KI-Inventar'!$A$6:$A$65,0)),"")) | K14: =IF(A14="","",IF(OR(C14="",D14="",G14="",J14="",COUNTIF(C14:D14,"Prüfung offen")>0,COUNTIF(H14:I14,"Prüfung offen")>0,AND(D14="Ja",OR(E14="",E14="noch offen")),AND(G14<>"keiner",OR(H14="",AND(H14<>"Ja",I14="")))),"noch offen — Angaben unvollständig",IF(C14="Ja","VERBOTEN (Art. 5)",IF(AND(D14="Ja",E14="Abschnitt B",G14<>"keiner"),"Hochrisiko Anhang I Abschnitt B UND Anhang III — gesondert prüfen",IF(AND(D14="Ja",E14="Abschnitt B"),"Hochrisiko Anhang I Abschnitt B (Sektorrecht)",IF(AND(D14="Ja",G14<>"keiner"),"Hochrisiko Anhang I Abschnitt A und Anhang III",IF(D14="Ja","Hochrisiko Anhang I Abschnitt A",IF(G14<>"keiner",IF(H14="Ja","Hochrisiko Anhang III",IF(I14="Ja","Kein Hochrisiko (Art. 6 Abs. 3)","Hochrisiko Anhang III")),IF(J14<>"keiner","Transparenzpflicht (Art. 50)","Geringes Risiko"))))))))) | L14: =IF(K14="","",IF(K14="VERBOTEN (Art. 5)","02.02.2025 (NCII/CSAM: 02.12.2026)",IF(LEFT(K14,10)="noch offen","keine Frist — Einstufung zuerst abschließen",IF(K14="Hochrisiko Anhang I Abschnitt B (Sektorrecht)","Kapitel III gilt nicht. Es gelten nur Art. 6 Abs. 1, Art. 60a und Art. 102–112 (Art. 2 Abs. 2 n. F.). Frist und Pflichten folgen aus dem Sektorrecht — bei Maschinen: Anhang III VO (EU) 2023/1230, delegierter Rechtsakt ab 02.08.2028.",IF(K14="Hochrisiko Anhang I Abschnitt B UND Anhang III — gesondert prüfen","Uneinheitlich: Für den Anhang-I-Teil gilt Art. 2 Abs. 2 n. F. (nur Art. 6 Abs. 1, 60a, 102–112), für den Anhang-III-Teil der 02.12.2027. Juristisch klären.",IF(K14="Hochrisiko Anhang I Abschnitt A und Anhang III","02.12.2027 (Anhang III) / 02.08.2028 (Anhang I Abschnitt A) — Planungsannahme",IF(K14="Hochrisiko Anhang I Abschnitt A","02.08.2028 — Planungsannahme; Vorbehalt delegierter Rechtsakte nach Art. 2 Abs. 13 n. F. (bis 02.08.2027)",IF(K14="Hochrisiko Anhang III","02.12.2027 — Planungsannahme",IF(K14="Transparenzpflicht (Art. 50)","02.08.2026",IF(K14="Kein Hochrisiko (Art. 6 Abs. 3)","Registrierung nach Art. 49 Abs. 2; Bewertung VOR Inverkehrbringen dokumentieren","keine besonderen Pflichten aus den hier geprüften Kategorien — Art. 4 und übriges Recht (DSGVO, Arbeitsrecht, Urheberrecht) weiter prüfen")))))))))) | M14: =IF(K14="","",IF(LEFT(K14,10)="noch offen","noch offen",IF(K14="Kein Hochrisiko (Art. 6 Abs. 3)","Ja — Art. 49 Abs. 2 (Anbieter); Bewertung VOR Inverkehrbringen dokumentieren (Art. 6 Abs. 4)",IF(K14="Hochrisiko Anhang I Abschnitt B (Sektorrecht)","Nein — Art. 49 ist nach Art. 2 Abs. 2 n. F. nicht anwendbar",IF(K14="Hochrisiko Anhang I Abschnitt A","Nein — Art. 49 Abs. 1 gilt nur für Anhang III",IF(AND(LEFT(G14,1)="2",ISNUMBER(SEARCH("Anhang III",K14))),"Nein — Registrierung auf nationaler Ebene (Art. 49 Abs. 5)",IF(ISNUMBER(SEARCH("Anhang III",K14)),"Ja — Art. 49 Abs. 1 (Anbieter); Behörden als Betreiber: Art. 49 Abs. 3","Nein"))))))) | N14: =IF(A14="","",IF(K14="VERBOTEN (Art. 5)","entfällt — Einsatz unzulässig",IF(K14="Hochrisiko Anhang I Abschnitt B (Sektorrecht)","Nein — Art. 50 ist nach Art. 2 Abs. 2 n. F. nicht anwendbar",IF(AND(J14<>"",J14<>"keiner"),"Ja — Art. 50 gilt zusätzlich ab 02.08.2026","Nein")))) | P14: =IF(K14="","",IF(LEFT(K14,10)="noch offen","Prüfung unvollständig",IF(O14="Ja","Einstufung bestätigt",IF(O14="Nein","Juristische Prüfung erforderlich","Arbeitsannahme — nicht bestätigt"))))
B15: =IF(A15="","",IFERROR(INDEX('01_KI-Inventar'!$B$6:$B$65,MATCH(A15,'01_KI-Inventar'!$A$6:$A$65,0)),"")) | K15: =IF(A15="","",IF(OR(C15="",D15="",G15="",J15="",COUNTIF(C15:D15,"Prüfung offen")>0,COUNTIF(H15:I15,"Prüfung offen")>0,AND(D15="Ja",OR(E15="",E15="noch offen")),AND(G15<>"keiner",OR(H15="",AND(H15<>"Ja",I15="")))),"noch offen — Angaben unvollständig",IF(C15="Ja","VERBOTEN (Art. 5)",IF(AND(D15="Ja",E15="Abschnitt B",G15<>"keiner"),"Hochrisiko Anhang I Abschnitt B UND Anhang III — gesondert prüfen",IF(AND(D15="Ja",E15="Abschnitt B"),"Hochrisiko Anhang I Abschnitt B (Sektorrecht)",IF(AND(D15="Ja",G15<>"keiner"),"Hochrisiko Anhang I Abschnitt A und Anhang III",IF(D15="Ja","Hochrisiko Anhang I Abschnitt A",IF(G15<>"keiner",IF(H15="Ja","Hochrisiko Anhang III",IF(I15="Ja","Kein Hochrisiko (Art. 6 Abs. 3)","Hochrisiko Anhang III")),IF(J15<>"keiner","Transparenzpflicht (Art. 50)","Geringes Risiko"))))))))) | L15: =IF(K15="","",IF(K15="VERBOTEN (Art. 5)","02.02.2025 (NCII/CSAM: 02.12.2026)",IF(LEFT(K15,10)="noch offen","keine Frist — Einstufung zuerst abschließen",IF(K15="Hochrisiko Anhang I Abschnitt B (Sektorrecht)","Kapitel III gilt nicht. Es gelten nur Art. 6 Abs. 1, Art. 60a und Art. 102–112 (Art. 2 Abs. 2 n. F.). Frist und Pflichten folgen aus dem Sektorrecht — bei Maschinen: Anhang III VO (EU) 2023/1230, delegierter Rechtsakt ab 02.08.2028.",IF(K15="Hochrisiko Anhang I Abschnitt B UND Anhang III — gesondert prüfen","Uneinheitlich: Für den Anhang-I-Teil gilt Art. 2 Abs. 2 n. F. (nur Art. 6 Abs. 1, 60a, 102–112), für den Anhang-III-Teil der 02.12.2027. Juristisch klären.",IF(K15="Hochrisiko Anhang I Abschnitt A und Anhang III","02.12.2027 (Anhang III) / 02.08.2028 (Anhang I Abschnitt A) — Planungsannahme",IF(K15="Hochrisiko Anhang I Abschnitt A","02.08.2028 — Planungsannahme; Vorbehalt delegierter Rechtsakte nach Art. 2 Abs. 13 n. F. (bis 02.08.2027)",IF(K15="Hochrisiko Anhang III","02.12.2027 — Planungsannahme",IF(K15="Transparenzpflicht (Art. 50)","02.08.2026",IF(K15="Kein Hochrisiko (Art. 6 Abs. 3)","Registrierung nach Art. 49 Abs. 2; Bewertung VOR Inverkehrbringen dokumentieren","keine besonderen Pflichten aus den hier geprüften Kategorien — Art. 4 und übriges Recht (DSGVO, Arbeitsrecht, Urheberrecht) weiter prüfen")))))))))) | M15: =IF(K15="","",IF(LEFT(K15,10)="noch offen","noch offen",IF(K15="Kein Hochrisiko (Art. 6 Abs. 3)","Ja — Art. 49 Abs. 2 (Anbieter); Bewertung VOR Inverkehrbringen dokumentieren (Art. 6 Abs. 4)",IF(K15="Hochrisiko Anhang I Abschnitt B (Sektorrecht)","Nein — Art. 49 ist nach Art. 2 Abs. 2 n. F. nicht anwendbar",IF(K15="Hochrisiko Anhang I Abschnitt A","Nein — Art. 49 Abs. 1 gilt nur für Anhang III",IF(AND(LEFT(G15,1)="2",ISNUMBER(SEARCH("Anhang III",K15))),"Nein — Registrierung auf nationaler Ebene (Art. 49 Abs. 5)",IF(ISNUMBER(SEARCH("Anhang III",K15)),"Ja — Art. 49 Abs. 1 (Anbieter); Behörden als Betreiber: Art. 49 Abs. 3","Nein"))))))) | N15: =IF(A15="","",IF(K15="VERBOTEN (Art. 5)","entfällt — Einsatz unzulässig",IF(K15="Hochrisiko Anhang I Abschnitt B (Sektorrecht)","Nein — Art. 50 ist nach Art. 2 Abs. 2 n. F. nicht anwendbar",IF(AND(J15<>"",J15<>"keiner"),"Ja — Art. 50 gilt zusätzlich ab 02.08.2026","Nein")))) | P15: =IF(K15="","",IF(LEFT(K15,10)="noch offen","Prüfung unvollständig",IF(O15="Ja","Einstufung bestätigt",IF(O15="Nein","Juristische Prüfung erforderlich","Arbeitsannahme — nicht bestätigt"))))
B16: =IF(A16="","",IFERROR(INDEX('01_KI-Inventar'!$B$6:$B$65,MATCH(A16,'01_KI-Inventar'!$A$6:$A$65,0)),"")) | K16: =IF(A16="","",IF(OR(C16="",D16="",G16="",J16="",COUNTIF(C16:D16,"Prüfung offen")>0,COUNTIF(H16:I16,"Prüfung offen")>0,AND(D16="Ja",OR(E16="",E16="noch offen")),AND(G16<>"keiner",OR(H16="",AND(H16<>"Ja",I16="")))),"noch offen — Angaben unvollständig",IF(C16="Ja","VERBOTEN (Art. 5)",IF(AND(D16="Ja",E16="Abschnitt B",G16<>"keiner"),"Hochrisiko Anhang I Abschnitt B UND Anhang III — gesondert prüfen",IF(AND(D16="Ja",E16="Abschnitt B"),"Hochrisiko Anhang I Abschnitt B (Sektorrecht)",IF(AND(D16="Ja",G16<>"keiner"),"Hochrisiko Anhang I Abschnitt A und Anhang III",IF(D16="Ja","Hochrisiko Anhang I Abschnitt A",IF(G16<>"keiner",IF(H16="Ja","Hochrisiko Anhang III",IF(I16="Ja","Kein Hochrisiko (Art. 6 Abs. 3)","Hochrisiko Anhang III")),IF(J16<>"keiner","Transparenzpflicht (Art. 50)","Geringes Risiko"))))))))) | L16: =IF(K16="","",IF(K16="VERBOTEN (Art. 5)","02.02.2025 (NCII/CSAM: 02.12.2026)",IF(LEFT(K16,10)="noch offen","keine Frist — Einstufung zuerst abschließen",IF(K16="Hochrisiko Anhang I Abschnitt B (Sektorrecht)","Kapitel III gilt nicht. Es gelten nur Art. 6 Abs. 1, Art. 60a und Art. 102–112 (Art. 2 Abs. 2 n. F.). Frist und Pflichten folgen aus dem Sektorrecht — bei Maschinen: Anhang III VO (EU) 2023/1230, delegierter Rechtsakt ab 02.08.2028.",IF(K16="Hochrisiko Anhang I Abschnitt B UND Anhang III — gesondert prüfen","Uneinheitlich: Für den Anhang-I-Teil gilt Art. 2 Abs. 2 n. F. (nur Art. 6 Abs. 1, 60a, 102–112), für den Anhang-III-Teil der 02.12.2027. Juristisch klären.",IF(K16="Hochrisiko Anhang I Abschnitt A und Anhang III","02.12.2027 (Anhang III) / 02.08.2028 (Anhang I Abschnitt A) — Planungsannahme",IF(K16="Hochrisiko Anhang I Abschnitt A","02.08.2028 — Planungsannahme; Vorbehalt delegierter Rechtsakte nach Art. 2 Abs. 13 n. F. (bis 02.08.2027)",IF(K16="Hochrisiko Anhang III","02.12.2027 — Planungsannahme",IF(K16="Transparenzpflicht (Art. 50)","02.08.2026",IF(K16="Kein Hochrisiko (Art. 6 Abs. 3)","Registrierung nach Art. 49 Abs. 2; Bewertung VOR Inverkehrbringen dokumentieren","keine besonderen Pflichten aus den hier geprüften Kategorien — Art. 4 und übriges Recht (DSGVO, Arbeitsrecht, Urheberrecht) weiter prüfen")))))))))) | M16: =IF(K16="","",IF(LEFT(K16,10)="noch offen","noch offen",IF(K16="Kein Hochrisiko (Art. 6 Abs. 3)","Ja — Art. 49 Abs. 2 (Anbieter); Bewertung VOR Inverkehrbringen dokumentieren (Art. 6 Abs. 4)",IF(K16="Hochrisiko Anhang I Abschnitt B (Sektorrecht)","Nein — Art. 49 ist nach Art. 2 Abs. 2 n. F. nicht anwendbar",IF(K16="Hochrisiko Anhang I Abschnitt A","Nein — Art. 49 Abs. 1 gilt nur für Anhang III",IF(AND(LEFT(G16,1)="2",ISNUMBER(SEARCH("Anhang III",K16))),"Nein — Registrierung auf nationaler Ebene (Art. 49 Abs. 5)",IF(ISNUMBER(SEARCH("Anhang III",K16)),"Ja — Art. 49 Abs. 1 (Anbieter); Behörden als Betreiber: Art. 49 Abs. 3","Nein"))))))) | N16: =IF(A16="","",IF(K16="VERBOTEN (Art. 5)","entfällt — Einsatz unzulässig",IF(K16="Hochrisiko Anhang I Abschnitt B (Sektorrecht)","Nein — Art. 50 ist nach Art. 2 Abs. 2 n. F. nicht anwendbar",IF(AND(J16<>"",J16<>"keiner"),"Ja — Art. 50 gilt zusätzlich ab 02.08.2026","Nein")))) | P16: =IF(K16="","",IF(LEFT(K16,10)="noch offen","Prüfung unvollständig",IF(O16="Ja","Einstufung bestätigt",IF(O16="Nein","Juristische Prüfung erforderlich","Arbeitsannahme — nicht bestätigt"))))
